Workbook

Sheet Assumptions
A1: InhabitMe — Fee Model & Pricing Assumptions
A2: Blue = editable inputs | Black = calculated | Yellow = key assumptions requiring review
A4: Fee Structure — InhabitMe (both sides pay flat fee)
A5: Duration Tier | B5: Duration (months) | C5: Guest Fee (€) | D5: Host Fee (€) | E5: Total per txn (€) | F5: Notes
A6: Tier 1 — Short | B6: 1 | C6: 79 | D6: 49 | E6: =C6+D6 -> 128 | F6: Confirmed by founder
A7: Tier 2 — Mid | B7: 2–3 | C7: 139 | D7: 79 | E7: =C7+D7 -> 218 | F7: Confirmed by founder
A8: Tier 3 — Standard | B8: 4–6 | C8: 189 | D8: 99 | E8: =C8+D8 -> 288 | F8: Confirmed by founder
A9: Tier 4 — Long | B9: 7+ | C9: 239 | D9: 119 | E9: =C9+D9 -> 358 | F9: Confirmed by founder
A10: Weighted avg total fee (equal txn weight) | E10: =AVERAGE(E6:E9) -> 248
A12: Market Reference — Avg Rental Values (Spain/Portugal)
A13: City | B13: Avg Rent/mo (€) | C13: Avg Duration (mo) | D13: Avg Booking Value (€) | E13: InhabitMe fee % | F13: Airbnb fee %
A14: Madrid | B14: 1400 | C14: 3 | D14: =B14*C14 -> 4200 | E14: =IF(C14<=1,E6,IF(C14<=3,E7,IF(C14<=6,E8,E9)))/D14 -> 0.051904762 | F14: 0.17
A15: Barcelona | B15: 1600 | C15: 3 | D15: =B15*C15 -> 4800 | E15: =IF(C15<=1,E6,IF(C15<=3,E7,IF(C15<=6,E8,E9)))/D15 -> 0.045416667 | F15: 0.17
A16: Valencia | B16: 900 | C16: 2 | D16: =B16*C16 -> 1800 | E16: =IF(C16<=1,E6,IF(C16<=3,E7,IF(C16<=6,E8,E9)))/D16 -> 0.12111111 | F16: 0.17
A17: Lisbon | B17: 1300 | C17: 3 | D17: =B17*C17 -> 3900 | E17: =IF(C17<=1,E6,IF(C17<=3,E7,IF(C17<=6,E8,E9)))/D17 -> 0.055897436 | F17: 0.17
A18: Seville | B18: 800 | C18: 2 | D18: =B18*C18 -> 1600 | E18: =IF(C18<=1,E6,IF(C18<=3,E7,IF(C18<=6,E8,E9)))/D18 -> 0.13625 | F18: 0.17
A20: Volume Assumptions (transactions / month)
A21: Scenario | B21: Y1 Start | C21: Y1 End | D21: Y2 End | E21: Y3 End | F21: Notes
A22: Bear 🐻 | B22: 2 | C22: 8 | D22: 20 | E22: 45 | F22: Slow adoption, high CAC
A23: Base 📊 | B23: 5 | C23: 20 | D23: 60 | E23: 140 | F23: Moderate growth, organic + paid
A24: Bull 🚀 | B24: 10 | C24: 40 | D24: 120 | E24: 300 | F24: Strong network effects, PR traction
A26: Tier Mix Assumption (% of transactions per tier)
A27: Tier | B27: % of txns | C27: Total fee (€) | D27: Weighted contrib (€)
A28: Tier 1 — Short | B28: 0.15 | C28: 128 | D28: =B28*C28 -> 19.2
A29: Tier 2 — Mid | B29: 0.4 | C29: 218 | D29: =B29*C29 -> 87.2
A30: Tier 3 — Standard | B30: 0.35 | C30: 288 | D30: =B30*C30 -> 100.8
A31: Tier 4 — Long | B31: 0.1 | C31: 358 | D31: =B31*C31 -> 35.8
A32: Blended avg fee / transaction | D32: =SUM(D28:D31) -> 243
A33: Mix sums to 100%? | C33: =SUM(B28:B31) -> 1 | D33: =IF(ABS(C33-1)<0.001,"✓ OK","⚠ CHECK") -> ✓ OK

Sheet Competitive Analysis
A1: InhabitMe — Competitive Fee Analysis (Mid-Term Rental Platforms)
A2: Source: Public platform fee disclosures, Q1 2025. All figures in EUR. Assumes 3-month stay @ €1,400/mo = €4,200 booking value.
A4: Platform | B4: Target Market | C4: Guest Fee % | D4: Guest Fee €* | E4: Host Fee % | F4: Host Fee €* | G4: Total Fee €* | H4: vs InhabitMe | I4: Positioning | J4: Min Stay
A5: InhabitMe 🏠 | B5: Mid-term (1-6mo) | C5: Flat | D5: 189 | E5: Flat | F5: 99 | G5: =D5+F5 -> 288 | H5: — | I5: Flat fee — no % of rent. Base scenario Tier 3. | J5: 1 month
A6: Airbnb | B6: Short → mid-term | C6: 0.14 | D6: 588 | E6: 0.03 | F6: 126 | G6: =D6+F6 -> 714 | H6: =D6+F6-$G$5 -> 426 | I6: Guest 14%; Host 3% (split-fee model) | J6: 1 night
A7: Booking.com | B7: Short → mid-term | C7: 0 | D7: 0 | E7: 0.15 | F7: 630 | G7: =D7+F7 -> 630 | H7: =D7+F7-$G$5 -> 342 | I7: Host pays 15% commission; guest fee varies | J7: 1 night
A8: Spotahome | B8: Mid-term (1-11mo) | C8: 0.1 | D8: 420 | E8: 0 | F8: 0 | G8: =D8+F8 -> 420 | H8: =D8+F8-$G$5 -> 132 | I8: Guest booking fee ~10%; host pays €0 | J8: 1 month
A9: Homefully | B9: Mid-term (1-12mo) | C9: 0.05 | D9: 210 | E9: 0.07 | F9: 294 | G9: =D9+F9 -> 504 | H9: =D9+F9-$G$5 -> 216 | I9: ~5% guest + 7% host; pricing opaque | J9: 1 month
A10: HousingAnywhere | B10: Mid-term (3-12mo) | C10: 0.185 | D10: 777 | E10: 0 | F10: 0 | G10: =D10+F10 -> 777 | H10: =D10+F10-$G$5 -> 489 | I10: 18.5% booking fee (guest only) | J10: 3 months
A11: Flatio | B11: Mid-term (1-12mo) | C11: 0.05 | D11: 210 | E11: 0.05 | F11: 210 | G11: =D11+F11 -> 420 | H11: =D11+F11-$G$5 -> 132 | I11: ~5% each side; €0 for direct bookings | J11: 1 month
A12: Idealista Rent | B12: Long-term focus | C12: 0 | D12: 0 | E12: 0.08 | F12: 336 | G12: =D12+F12 -> 336 | H12: =D12+F12-$G$5 -> 48 | I12: Host pays ~8-10% agency; guest pays €0 | J12: 12 months
A13: Uniplaces | B13: Student/mid-term | C13: 0.09 | D13: 378 | E13: 0.04 | F13: 168 | G13: =D13+F13 -> 546 | H13: =D13+F13-$G$5 -> 258 | I13: ~9% guest + 4% host | J13: 1 month
A14: * Reference: 3-month stay at €1,400/month = €4,200 total booking value. InhabitMe flat fee for Tier 3 (4-6 months) used as benchmark.
A15: Key Insight: InhabitMe's flat-fee model is 60–80% cheaper than percentage-based competitors on mid-value bookings, while remaining profitable at scale.
A17: Feature Comparison
A18: Feature | B18: InhabitMe | C18: Airbnb | D18: Spotahome | E18: HousingAnywhere | F18: Flatio | G18: Homefully
A19: Fee model | B19: Flat fee both sides | C19: % both sides | D19: % guest only | E19: % guest only | F19: % both sides | G19: % both sides
A20: Mid-term focus | B20: ✅ Core focus | C20: ⚠ Secondary | D20: ✅ Yes | E20: ✅ Yes | F20: ✅ Yes | G20: ✅ Yes
A21: Remote work amenities | B21: ✅ Verified WiFi+desk | C21: ❌ No | D21: ❌ No | E21: ❌ No | F21: ❌ No | G21: ❌ No
A22: Price transparency | B22: ✅ Flat — no surprises | C22: ⚠ Complex | D22: ⚠ Varies | E22: ⚠ Varies | F22: ⚠ Varies | G22: ⚠ Varies
A23: Host lead unlock | B23: ✅ HOT/WARM/COLD | C23: ❌ No | D23: ❌ No | E23: ❌ No | F23: ❌ No | G23: ❌ No
A24: Coverage | B24: 🇪🇸🇵🇹 Spain+PT | C24: 🌍 Global | D24: 🌍 Global | E24: 🌍 Global | F24: 🇪🇺 Europe | G24: 🇪🇺 Europe

Sheet Revenue Projections
A1: InhabitMe — Revenue Projections (3-Year Model, Monthly)
A2: Blended avg fee per transaction pulled from Assumptions sheet. Scenarios: Bear / Base / Bull.
A4: Key Inputs (linked from Assumptions)
A5: Blended avg fee / txn (€) | B5: =Assumptions!D32 -> 243
A6: Bear — Y1 start txns/mo | B6: =Assumptions!B22 -> 2
A7: Bear — Y1 end txns/mo | B7: =Assumptions!C22 -> 8
A8: Bear — Y2 end txns/mo | B8: =Assumptions!D22 -> 20
A9: Bear — Y3 end txns/mo | B9: =Assumptions!E22 -> 45
A10: Base — Y1 start txns/mo | B10: =Assumptions!B23 -> 5
A11: Base — Y1 end txns/mo | B11: =Assumptions!C23 -> 20
A12: Base — Y2 end txns/mo | B12: =Assumptions!D23 -> 60
A13: Base — Y3 end txns/mo | B13: =Assumptions!E23 -> 140
A14: Bull — Y1 start txns/mo | B14: =Assumptions!B24 -> 10
A15: Bull — Y1 end txns/mo | B15: =Assumptions!C24 -> 40
A16: Bull — Y2 end txns/mo | B16: =Assumptions!D24 -> 120
A17: Bull — Y3 end txns/mo | B17: =Assumptions!E24 -> 300
A20: Period | B20: Bear — Transactions | C20: Bear — Revenue (€) | D20: Base — Transactions | E20: Base — Revenue (€) | F20: Bull — Transactions | G20: Bull — Revenue (€)
A21: Y1 M01 | B21: =MAX(0,ROUND($B$6+($B$7-$B$6)*0/11,0)) -> 2 | C21: =B21*$B$5 -> 486 | D21: =MAX(0,ROUND($B$10+($B$11-$B$10)*0/11,0)) -> 5 | E21: =D21*$B$5 -> 1215 | F21: =MAX(0,ROUND($B$14+($B$15-$B$14)*0/11,0)) -> 10 | G21: =F21*$B$5 -> 2430
A22: Y1 M02 | B22: =MAX(0,ROUND($B$6+($B$7-$B$6)*1/11,0)) -> 3 | C22: =B22*$B$5 -> 729 | D22: =MAX(0,ROUND($B$10+($B$11-$B$10)*1/11,0)) -> 6 | E22: =D22*$B$5 -> 1458 | F22: =MAX(0,ROUND($B$14+($B$15-$B$14)*1/11,0)) -> 13 | G22: =F22*$B$5 -> 3159
A23: Y1 M03 | B23: =MAX(0,ROUND($B$6+($B$7-$B$6)*2/11,0)) -> 3 | C23: =B23*$B$5 -> 729 | D23: =MAX(0,ROUND($B$10+($B$11-$B$10)*2/11,0)) -> 8 | E23: =D23*$B$5 -> 1944 | F23: =MAX(0,ROUND($B$14+($B$15-$B$14)*2/11,0)) -> 15 | G23: =F23*$B$5 -> 3645
A24: Y1 M04 | B24: =MAX(0,ROUND($B$6+($B$7-$B$6)*3/11,0)) -> 4 | C24: =B24*$B$5 -> 972 | D24: =MAX(0,ROUND($B$10+($B$11-$B$10)*3/11,0)) -> 9 | E24: =D24*$B$5 -> 2187 | F24: =MAX(0,ROUND($B$14+($B$15-$B$14)*3/11,0)) -> 18 | G24: =F24*$B$5 -> 4374
A25: Y1 M05 | B25: =MAX(0,ROUND($B$6+($B$7-$B$6)*4/11,0)) -> 4 | C25: =B25*$B$5 -> 972 | D25: =MAX(0,ROUND($B$10+($B$11-$B$10)*4/11,0)) -> 10 | E25: =D25*$B$5 -> 2430 | F25: =MAX(0,ROUND($B$14+($B$15-$B$14)*4/11,0)) -> 21 | G25: =F25*$B$5 -> 5103
A26: Y1 M06 | B26: =MAX(0,ROUND($B$6+($B$7-$B$6)*5/11,0)) -> 5 | C26: =B26*$B$5 -> 1215 | D26: =MAX(0,ROUND($B$10+($B$11-$B$10)*5/11,0)) -> 12 | E26: =D26*$B$5 -> 2916 | F26: =MAX(0,ROUND($B$14+($B$15-$B$14)*5/11,0)) -> 24 | G26: =F26*$B$5 -> 5832
A27: Y1 M07 | B27: =MAX(0,ROUND($B$6+($B$7-$B$6)*6/11,0)) -> 5 | C27: =B27*$B$5 -> 1215 | D27: =MAX(0,ROUND($B$10+($B$11-$B$10)*6/11,0)) -> 13 | E27: =D27*$B$5 -> 3159 | F27: =MAX(0,ROUND($B$14+($B$15-$B$14)*6/11,0)) -> 26 | G27: =F27*$B$5 -> 6318
A28: Y1 M08 | B28: =MAX(0,ROUND($B$6+($B$7-$B$6)*7/11,0)) -> 6 | C28: =B28*$B$5 -> 1458 | D28: =MAX(0,ROUND($B$10+($B$11-$B$10)*7/11,0)) -> 15 | E28: =D28*$B$5 -> 3645 | F28: =MAX(0,ROUND($B$14+($B$15-$B$14)*7/11,0)) -> 29 | G28: =F28*$B$5 -> 7047
A29: Y1 M09 | B29: =MAX(0,ROUND($B$6+($B$7-$B$6)*8/11,0)) -> 6 | C29: =B29*$B$5 -> 1458 | D29: =MAX(0,ROUND($B$10+($B$11-$B$10)*8/11,0)) -> 16 | E29: =D29*$B$5 -> 3888 | F29: =MAX(0,ROUND($B$14+($B$15-$B$14)*8/11,0)) -> 32 | G29: =F29*$B$5 -> 7776
A30: Y1 M10 | B30: =MAX(0,ROUND($B$6+($B$7-$B$6)*9/11,0)) -> 7 | C30: =B30*$B$5 -> 1701 | D30: =MAX(0,ROUND($B$10+($B$11-$B$10)*9/11,0)) -> 17 | E30: =D30*$B$5 -> 4131 | F30: =MAX(0,ROUND($B$14+($B$15-$B$14)*9/11,0)) -> 35 | G30: =F30*$B$5 -> 8505
A31: Y1 M11 | B31: =MAX(0,ROUND($B$6+($B$7-$B$6)*10/11,0)) -> 7 | C31: =B31*$B$5 -> 1701 | D31: =MAX(0,ROUND($B$10+($B$11-$B$10)*10/11,0)) -> 19 | E31: =D31*$B$5 -> 4617 | F31: =MAX(0,ROUND($B$14+($B$15-$B$14)*10/11,0)) -> 37 | G31: =F31*$B$5 -> 8991
A32: Y1 M12 | B32: =MAX(0,ROUND($B$6+($B$7-$B$6)*11/11,0)) -> 8 | C32: =B32*$B$5 -> 1944 | D32: =MAX(0,ROUND($B$10+($B$11-$B$10)*11/11,0)) -> 20 | E32: =D32*$B$5 -> 4860 | F32: =MAX(0,ROUND($B$14+($B$15-$B$14)*11/11,0)) -> 40 | G32: =F32*$B$5 -> 9720
A33: Y2 M01 | B33: =MAX(0,ROUND($B$7+($B$8-$B$7)*0/11,0)) -> 8 | C33: =B33*$B$5 -> 1944 | D33: =MAX(0,ROUND($B$11+($B$12-$B$11)*0/11,0)) -> 20 | E33: =D33*$B$5 -> 4860 | F33: =MAX(0,ROUND($B$15+($B$16-$B$15)*0/11,0)) -> 40 | G33: =F33*$B$5 -> 9720
A34: Y2 M02 | B34: =MAX(0,ROUND($B$7+($B$8-$B$7)*1/11,0)) -> 9 | C34: =B34*$B$5 -> 2187 | D34: =MAX(0,ROUND($B$11+($B$12-$B$11)*1/11,0)) -> 24 | E34: =D34*$B$5 -> 5832 | F34: =MAX(0,ROUND($B$15+($B$16-$B$15)*1/11,0)) -> 47 | G34: =F34*$B$5 -> 11421
A35: Y2 M03 | B35: =MAX(0,ROUND($B$7+($B$8-$B$7)*2/11,0)) -> 10 | C35: =B35*$B$5 -> 2430 | D35: =MAX(0,ROUND($B$11+($B$12-$B$11)*2/11,0)) -> 27 | E35: =D35*$B$5 -> 6561 | F35: =MAX(0,ROUND($B$15+($B$16-$B$15)*2/11,0)) -> 55 | G35: =F35*$B$5 -> 13365
A36: Y2 M04 | B36: =MAX(0,ROUND($B$7+($B$8-$B$7)*3/11,0)) -> 11 | C36: =B36*$B$5 -> 2673 | D36: =MAX(0,ROUND($B$11+($B$12-$B$11)*3/11,0)) -> 31 | E36: =D36*$B$5 -> 7533 | F36: =MAX(0,ROUND($B$15+($B$16-$B$15)*3/11,0)) -> 62 | G36: =F36*$B$5 -> 15066
A37: Y2 M05 | B37: =MAX(0,ROUND($B$7+($B$8-$B$7)*4/11,0)) -> 12 | C37: =B37*$B$5 -> 2916 | D37: =MAX(0,ROUND($B$11+($B$12-$B$11)*4/11,0)) -> 35 | E37: =D37*$B$5 -> 8505 | F37: =MAX(0,ROUND($B$15+($B$16-$B$15)*4/11,0)) -> 69 | G37: =F37*$B$5 -> 16767
A38: Y2 M06 | B38: =MAX(0,ROUND($B$7+($B$8-$B$7)*5/11,0)) -> 13 | C38: =B38*$B$5 -> 3159 | D38: =MAX(0,ROUND($B$11+($B$12-$B$11)*5/11,0)) -> 38 | E38: =D38*$B$5 -> 9234 | F38: =MAX(0,ROUND($B$15+($B$16-$B$15)*5/11,0)) -> 76 | G38: =F38*$B$5 -> 18468
A39: Y2 M07 | B39: =MAX(0,ROUND($B$7+($B$8-$B$7)*6/11,0)) -> 15 | C39: =B39*$B$5 -> 3645 | D39: =MAX(0,ROUND($B$11+($B$12-$B$11)*6/11,0)) -> 42 | E39: =D39*$B$5 -> 10206 | F39: =MAX(0,ROUND($B$15+($B$16-$B$15)*6/11,0)) -> 84 | G39: =F39*$B$5 -> 20412
A40: Y2 M08 | B40: =MAX(0,ROUND($B$7+($B$8-$B$7)*7/11,0)) -> 16 | C40: =B40*$B$5 -> 3888 | D40: =MAX(0,ROUND($B$11+($B$12-$B$11)*7/11,0)) -> 45 | E40: =D40*$B$5 -> 10935 | F40: =MAX(0,ROUND($B$15+($B$16-$B$15)*7/11,0)) -> 91 | G40: =F40*$B$5 -> 22113
A41: Y2 M09 | B41: =MAX(0,ROUND($B$7+($B$8-$B$7)*8/11,0)) -> 17 | C41: =B41*$B$5 -> 4131 | D41: =MAX(0,ROUND($B$11+($B$12-$B$11)*8/11,0)) -> 49 | E41: =D41*$B$5 -> 11907 | F41: =MAX(0,ROUND($B$15+($B$16-$B$15)*8/11,0)) -> 98 | G41: =F41*$B$5 -> 23814
A42: Y2 M10 | B42: =MAX(0,ROUND($B$7+($B$8-$B$7)*9/11,0)) -> 18 | C42: =B42*$B$5 -> 4374 | D42: =MAX(0,ROUND($B$11+($B$12-$B$11)*9/11,0)) -> 53 | E42: =D42*$B$5 -> 12879 | F42: =MAX(0,ROUND($B$15+($B$16-$B$15)*9/11,0)) -> 105 | G42: =F42*$B$5 -> 25515
A43: Y2 M11 | B43: =MAX(0,ROUND($B$7+($B$8-$B$7)*10/11,0)) -> 19 | C43: =B43*$B$5 -> 4617 | D43: =MAX(0,ROUND($B$11+($B$12-$B$11)*10/11,0)) -> 56 | E43: =D43*$B$5 -> 13608 | F43: =MAX(0,ROUND($B$15+($B$16-$B$15)*10/11,0)) -> 113 | G43: =F43*$B$5 -> 27459
...

Sheet Unit Economics
A1: InhabitMe — Unit Economics per Transaction
A3: Revenue per Transaction by Tier
A4: Tier | B4: Duration | C4: Guest Fee | D4: Host Fee | E4: Gross Revenue | F4: vs Airbnb (€) | G4: vs Airbnb (%) | H4: Savings to users
A5: Tier 1 — Short | B5: 1 | C5: 79 | D5: 49 | E5: =C5+D5 -> 128 | F5: 204 | G5: =(E5)/F5 -> 0.62745098 | H5: =F5-E5 -> 76
A6: Tier 2 — Mid | B6: 2–3 | C6: 139 | D6: 79 | E6: =C6+D6 -> 218 | F6: 510 | G6: =(E6)/F6 -> 0.42745098 | H6: =F6-E6 -> 292
A7: Tier 3 — Standard | B7: 4–6 | C7: 189 | D7: 99 | E7: =C7+D7 -> 288 | F7: 1020 | G7: =(E7)/F7 -> 0.28235294 | H7: =F7-E7 -> 732
A8: Tier 4 — Long | B8: 7+ | C8: 239 | D8: 119 | E8: =C8+D8 -> 358 | F8: 1836 | G8: =(E8)/F8 -> 0.19498911 | H8: =F8-E8 -> 1478
A9: Average (equal weight) | C9: =AVERAGE(C5:C8) -> 161.5 | D9: =AVERAGE(D5:D8) -> 86.5 | E9: =AVERAGE(E5:E8) -> 248 | F9: =AVERAGE(F5:F8) -> 892.5 | G9: =AVERAGE(G5:G8) -> 0.383061 | H9: =AVERAGE(H5:H8) -> 644.5
A11: Breakeven & Scale Milestones
A12: Milestone | B12: Monthly Txns needed | C12: Monthly Revenue (€) | D12: Annual Revenue (€) | E12: Notes
A13: Cover 1 FTE (€3,000/mo) | B13: =CEILING(3000/Assumptions!D32,1) -> 13 | C13: 3000 | D13: =C13*12 -> 36000 | E13: ~1 hire
A14: Cover 2 FTE (€6,000/mo) | B14: =CEILING(6000/Assumptions!D32,1) -> 25 | C14: 6000 | D14: =C14*12 -> 72000 | E14: ~2 hires
A15: Cover 5 FTE (€15,000/mo) | B15: =CEILING(15000/Assumptions!D32,1) -> 62 | C15: 15000 | D15: =C15*12 -> 180000 | E15: ~5 hires
A16: €100K ARR | B16: =CEILING(8333.33333333333/Assumptions!D32,1) -> 35 | C16: 8333.3333 | D16: =C16*12 -> 100000 | E16: Key SaaS milestone
A17: €500K ARR | B17: =CEILING(41666.6666666667/Assumptions!D32,1) -> 172 | C17: 41666.667 | D17: =C17*12 -> 500000 | E17: Growth stage
A18: €1M ARR | B18: =CEILING(83333.3333333333/Assumptions!D32,1) -> 343 | C18: 83333.333 | D18: =C18*12 -> 1000000 | E18: Scale stage
